Workbook

Sheet Revenue
A1: Particulars | C1: Historical | G1: Forecast
B2: Unit | C2: 2022 | D2: 2023 | E2: 2024 | F2: 2025 | G2: 2026 | H2: 2027 | I2: 2028 | J2: 2029 | K2: 2030
A4: U.S. — Franchised revenues | B4: $ | C4: =6585 -> 6585 | D4: 7163 | E4: 7211 | F4: 7371 | G4: =F4*(1+G7) -> 7657.6451 | H4: =G4*(1+H7) -> 7830.6508 | I4: =H4*(1+I7) -> 8049.0453 | J4: =I4*(1+J7) -> 8288.8277 | K4: =J4*(1+K7) -> 8510.6157
A5: Growth rate % | D5: =(D4-C4)/C4 -> 0.087775247 | E5: =(E4-D4)/D4 -> 0.0067011029 | F5: =(F4-E4)/E4 -> 0.022188323
A6: (+/-) Inorganic growth | D6: =0% -> 0 | E6: 0 | F6: =0 -> 0 | M6: Note inorganic growth is brought as +/- unlike our Coca-Cola
A7: Organic growth % | D7: =D5-D6 -> 0.087775247 | E7: =E5-E6 -> 0.0067011029 | F7: =F5-F6 -> 0.022188323 | G7: =AVERAGE(D7:F7) -> 0.038888224 | H7: =AVERAGE(E7:G7) -> 0.02259255 | I7: =AVERAGE(F7:H7) -> 0.027889699 | J7: =AVERAGE(G7:I7) -> 0.029790158 | K7: =AVERAGE(H7:J7) -> 0.026757469 | M7: example, so we subtract it from growth rate to get organic growth
A9: U.S. — Company-operated sales | C9: =2836 -> 2836 | D9: 3221 | E9: 3197 | F9: 3115 | G9: =F9*(1+G12) -> 3221.5895 | H9: =G9*(1+H12) -> 3222.7901 | I9: =H9*(1+I12) -> 3232.3959 | J9: =I9*(1+J12) -> 3272.8778 | K9: =J9*(1+K12) -> 3290.199
A10: Growth rate % | D10: =(D9-C9)/C9 -> 0.13575458 | E10: =(E9-D9)/D9 -> -0.0074511021 | F10: =(F9-E9)/E9 -> -0.025649046
A11: (+/-) Inorganic growth | D11: =0% -> 0 | E11: =0 -> 0 | F11: =0 -> 0
A12: Organic growth % | D12: =D10-D11 -> 0.13575458 | E12: =E10-E11 -> -0.0074511021 | F12: =F10-F11 -> -0.025649046 | G12: =AVERAGE(D12:F12) -> 0.034218145 | H12: =AVERAGE(E12:G12) -> 0.00037266571 | I12: =AVERAGE(F12:H12) -> 0.0029805883 | J12: =AVERAGE(G12:I12) -> 0.0125238 | K12: =AVERAGE(H12:J12) -> 0.0052923513
A14: International Operated Markets (IOM) — Franchised revenues | C14: =5985 -> 5985 | D14: 6549 | E14: 6746 | F14: 7279.49 | G14: =F14*(1+G17) -> 7675.977 | H14: =G14*(1+H17) -> 8017.8897 | I14: =H14*(1+I17) -> 8413.6847 | J14: =I14*(1+J17) -> 8829.8073 | K14: =J14*(1+K17) -> 9251.7692
A15: Growth rate % | D15: =(D14-C14)/C14 -> 0.094235589 | E15: =(E14-D14)/D14 -> 0.030080928 | F15: =(F14-E14)/E14 -> 0.079082419 | M15: Note: Inorganic growth was brought as follows:
A16: (+/-) Inorganic growth | D16: =1% -> 0.01 | E16: =0% -> 0 | F16: =3% -> 0.03 | M16: For example for 2025 year in revenues table (page 19) 8% was nominal growth. Also growth
A17: Organic growth % | D17: =D15-D16 -> 0.084235589 | E17: =E15-E16 -> 0.030080928 | F17: =F15-F16 -> 0.049082419 | G17: =AVERAGE(D17:F17) -> 0.054466312 | H17: =AVERAGE(E17:G17) -> 0.04454322 | I17: =AVERAGE(F17:H17) -> 0.049363984 | J17: =AVERAGE(G17:I17) -> 0.049457839 | K17: =AVERAGE(H17:J17) -> 0.047788347 | M17: excluding currency translation was 5%. So, by subtracting 5% from 8% we get part of inorganic
M18: growth coming from foreign exchange rate translation.Which is cell F16 in our table.
A19: International Operated Markets (IOM) — Company-operated sales | C19: =5179 -> 5179 | D19: 5702 | E19: 5713 | F19: 6131 | G19: =F19*(1+G22) -> 6449.9762 | H19: =G19*(1+H22) -> 6680.2885 | I19: =H19*(1+I22) -> 6994.041 | J19: =I19*(1+J22) -> 7308.0761 | K19: =J19*(1+K22) -> 7618.8515
A20: Growth rate % | D20: =(D19-C19)/C19 -> 0.10098475 | E20: =(E19-D19)/D19 -> 0.0019291477 | F20: =(F19-E19)/E19 -> 0.073166462
A21: (+/-) Inorganic growth | D21: =0% -> 0 | E21: =0% -> 0 | F21: =2% -> 0.02
A22: Organic growth % | D22: =D20-D21 -> 0.10098475 | E22: =E20-E21 -> 0.0019291477 | F22: =F20-F21 -> 0.053166462 | G22: =AVERAGE(D22:F22) -> 0.052026785 | H22: =AVERAGE(E22:G22) -> 0.035707465 | I22: =AVERAGE(F22:H22) -> 0.046966904 | J22: =AVERAGE(G22:I22) -> 0.044900385 | K22: =AVERAGE(H22:J22) -> 0.042524918
A24: International Developmental Licensed & Corporate (IDL) — Franchised revenues | C24: =1536 -> 1536 | D24: 1724 | E24: 1758 | F24: 1898.2 | G24: =F24*(1+G27) -> 2070.2194 | H24: =G24*(1+H27) -> 2215.1994 | I24: =H24*(1+I27) -> 2385.3291 | J24: =I24*(1+J27) -> 2574.1317 | K24: =J24*(1+K27) -> 2768.0358
A25: Growth rate % | D25: =(D24-C24)/C24 -> 0.12239583 | E25: =(E24-D24)/D24 -> 0.019721578 | F25: =(F24-E24)/E24 -> 0.079749716
A26: (+/-) Inorganic growth | D26: =-3% -> -0.03 | E26: =-3% -> -0.03 | F26: =1% -> 0.01
A27: Organic growth % | D27: =D25-D26 -> 0.15239583 | E27: =E25-E26 -> 0.049721578 | F27: =F25-F26 -> 0.069749716 | G27: =AVERAGE(D27:F27) -> 0.090622376 | H27: =AVERAGE(E27:G27) -> 0.070031223 | I27: =AVERAGE(F27:H27) -> 0.076801105 | J27: =AVERAGE(G27:I27) -> 0.079151568 | K27: =AVERAGE(H27:J27) -> 0.075327965
A29: International Developmental Licensed & Corporate (IDL) — Company-operated sales | C29: =733 -> 733 | D29: 819 | E29: 872 | F29: 443 | G29: =F29*(1+G32) -> 492.18167 | H29: =G29*(1+H32) -> 546.82346 | I29: =H29*(1+I32) -> 607.53156 | J29: =I29*(1+J32) -> 674.97945 | K29: =J29*(1+K32) -> 749.91537
A30: Growth rate % | D30: =(D29-C29)/C29 -> 0.11732606 | E30: =(E29-D29)/D29 -> 0.064713065 | F30: =(F29-E29)/E29 -> -0.49197248
A31: (+/-) Inorganic growth | D31: =-1% -> -0.01 | E31: =-3% -> -0.03 | F31: =0 -> 0
A32: Organic growth % | D32: =D30-D31 -> 0.12732606 | E32: =E30-E31 -> 0.094713065 | F32: =F30-F31 -> -0.49197248 | G32: =AVERAGE($D$32:$E$32) -> 0.11101956 | H32: =AVERAGE($D$32:$E$32) -> 0.11101956 | I32: =AVERAGE($D$32:$E$32) -> 0.11101956 | J32: =AVERAGE($D$32:$E$32) -> 0.11101956 | K32: =AVERAGE($D$32:$E$32) -> 0.11101956
A34: Other revenues | C34: =329 -> 329 | D34: =316 -> 316 | E34: =423 -> 423 | F34: =647 -> 647 | G34: =F34*(1+G37) -> 746.99188 | H34: =G34*(1+H37) -> 1067.5106 | I34: =H34*(1+I37) -> 1427.3138 | J34: =I34*(1+J37) -> 1843.8227 | K34: =J34*(1+K37) -> 2550.1249
A35: Growth rate % | D35: =(D34-C34)/C34 -> -0.039513678 | E35: =(E34-D34)/D34 -> 0.33860759 | F35: =(F34-E34)/E34 -> 0.52955083 | M35: Note that here we are using lagged average growth of 2 and 3 years ago, this way we'll replicate cyclical drop observed in 2025
A36: Inorganic growth % | D36: =-1% -> -0.01 | E36: =0 -> 0 | F36: =1% -> 0.01
A37: Organic growth % | D37: =D35-D36 -> -0.029513678 | E37: =E35-E36 -> 0.33860759 | F37: =F35-F36 -> 0.51955083 | G37: =AVERAGE(D37:E37) -> 0.15454696 | H37: =AVERAGE(E37:F37) -> 0.42907921 | I37: =AVERAGE(F37:G37) -> 0.33704889 | J37: =AVERAGE(G37:H37) -> 0.29181308 | K37: =AVERAGE(H37:I37) -> 0.38306405
A39: Total revenue | C39: =C34+C29+C24+C19+C14+C9+C4 -> 23183 | D39: =D34+D29+D24+D19+D14+D9+D4 -> 25494 | E39: =E34+E29+E24+E19+E14+E9+E4 -> 25920 | F39: =F34+F29+F24+F19+F14+F9+F4 -> 26884.69 | G39: =G34+G29+G24+G19+G14+G9+G4 -> 28314.581 | H39: =H34+H29+H24+H19+H14+H9+H4 -> 29581.153 | I39: =I34+I29+I24+I19+I14+I9+I4 -> 31109.341 | J39: =J34+J29+J24+J19+J14+J9+J4 -> 32792.523 | K39: =K34+K29+K24+K19+K14+K9+K4 -> 34739.511
A40: Check out the note for TR cell above

Sheet P&L
A1: Particulars | C1: Historical | G1: Forecast
B2: Unit | C2: 2022 | D2: 2023 | E2: 2024 | F2: 2025 | G2: 2026 | H2: 2027 | I2: 2028 | J2: 2029 | K2: 2030
A4: Total revenues | B4: $ | C4: =Revenue!C39 -> 23183 | D4: =Revenue!D39 -> 25494 | E4: =Revenue!E39 -> 25920 | F4: =Revenue!F39 -> 26884.69 | G4: =Revenue!G39 -> 28314.581 | H4: =Revenue!H39 -> 29581.153 | I4: =Revenue!I39 -> 31109.341 | J4: =Revenue!J39 -> 32792.523 | K4: =Revenue!K39 -> 34739.511
A5: Total Restaurant operaintg expenses | C5: =7381+2350+245 -> 9976 | D5: =2475+8224+232 -> 10931 | E5: =2536+8334+339 -> 11209 | F5: =2618+8268+564 -> 11450 | G5: =G4*(1-G32) -> 12157.02 | H5: =H4*(1-H32) -> 12693.731 | I5: =I4*(1-I32) -> 13352.206 | J5: =J4*(1-J32) -> 14048.041 | K5: =K4*(1-K32) -> 14903.815
A6: Gross Profit | C6: =C4-C5 -> 13207 | D6: =D4-D5 -> 14563 | E6: =E4-E5 -> 14711 | F6: =F4-F5 -> 15434.69 | G6: =G4-G5 -> 16157.561 | H6: =H4-H5 -> 16887.422 | I6: =I4-I5 -> 17757.135 | J6: =J4-J5 -> 18744.482 | K6: =K4-K5 -> 19835.697
A8: Selling, general and administrative expenses | C8: =370+2492 -> 2862 | D8: =382+2435 -> 2817 | E8: =447+2412 -> 2859 | F8: =2583+457 -> 3040 | G8: =G33*G4 -> 3237.2453 | H8: =H33*H4 -> 3314.6008 | I8: =I33*I4 -> 3497.926 | J8: =J33*J4 -> 3704.7167 | K8: =K33*K4 -> 3923.7988
A9: Other operating (income) expense net | C9: =974 -> 974 | D9: 99 | E9: 139.49 | F9: 2.1 | G9: =AVERAGE(E9:F9) -> 70.795 | H9: =AVERAGE(F9:G9) -> 36.4475 | I9: =AVERAGE(G9:H9) -> 53.62125 | J9: =AVERAGE(H9:I9) -> 45.034375 | K9: =AVERAGE(I9:J9) -> 49.327813
A10: Operating Income (EBIT) | C10: =C6-C8-C9 -> 9371 | D10: =D6-D8-D9 -> 11647 | E10: =E6-E8-E9 -> 11712.51 | F10: =F6-F8-F9 -> 12392.59 | G10: =G6-G8-G9 -> 12849.521 | H10: =H6-H8-H9 -> 13536.374 | I10: =I6-I8-I9 -> 14205.588 | J10: =J6-J8-J9 -> 14994.731 | K10: =K6-K8-K9 -> 15862.57
A12: Non operating interest (income) expense - NET | C12: 339 | D12: -236 | E12: -138.5 | F12: -86.5 | G12: 0 | H12: 0 | I12: 0 | J12: 0 | K12: 0
A13: Interest expense | C13: 1207 | D13: 1361 | E13: 1506 | F13: 1582 | G13: =Debt!C12 -> 828.72263 | H13: =Debt!D12 -> 927.15656 | I13: =Debt!E12 -> 997.02131 | J13: =Debt!F12 -> 995.74758 | K13: =Debt!G12 -> 1016.2334
A14: (+/-) Extraordinary items (Charges) | C14: 770.7 | D14: 273.7 | E14: =235.5 -> 235.5 | F14: 179 | G14: 0 | H14: 0 | I14: 0 | J14: 0 | K14: 0
A16: Normalized Income Before Income Taxes (PBT) | C16: =C10-C12-C13+C14 -> 8595.7 | D16: =D10-D12-D13+D14 -> 10795.7 | E16: =E10-E12-E13+E14 -> 10580.51 | F16: =F10-F12-F13+F14 -> 11076.09 | G16: =G10-G12-G13+G14 -> 12020.798 | H16: =H10-H12-H13+H14 -> 12609.217 | I16: =I10-I12-I13+I14 -> 13208.567 | J16: =J10-J12-J13+J14 -> 13998.983 | K16: =K10-K12-K13+K14 -> 14846.337
A18: Income taxes | C18: 1648 | D18: 2053 | E18: 2121.49 | F18: 2334
A19: (+/-) Extraordinary items (Tax settlement) | C19: 537.2 | D19: 0 | E19: 0 | F19: 0
A20: Normalized income taxes | C20: =C18-C19 -> 1110.8 | D20: =D18+D19 -> 2053 | E20: =E18+E19 -> 2121.49 | F20: =F18+F19 -> 2334 | G20: =G16*G35 -> 2195.6863 | H20: =H16*H35 -> 2471.5926 | I20: =I16*I35 -> 2608.3797 | J20: =J16*J35 -> 2753.854 | K20: =K16*K35 -> 2868.5592
A21: Consolidated Net Income (Normalized) | C21: =C16-C20 -> 7484.9 | D21: =D16-D20 -> 8742.7 | E21: =E16-E20 -> 8459.02 | F21: =F16-F20 -> 8742.09 | G21: =G16-G20 -> 9825.1118 | H21: =H16-H20 -> 10137.625 | I21: =I16-I20 -> 10600.187 | J21: =J16-J20 -> 11245.129 | K21: =K16-K20 -> 11977.777
A24: Supporting Variables:
A25: Diluted EPS | C25: 10.1 | D25: 11.94 | E25: 11.72 | F25: =12.2 -> 12.2 | G25: =G21/G26 -> 13.714561 | H25: =H21/H26 -> 14.150788 | I25: =I21/I26 -> 14.796464 | J25: =J21/J26 -> 15.696719 | K25: =K21/K26 -> 16.719399
A26: Average Shares Outstanding — Diluted | C26: 741.3 | D26: 732.3 | E26: 721.9 | F26: 716.4 | G26: =F26 -> 716.4 | H26: =G26 -> 716.4 | I26: =H26 -> 716.4 | J26: =I26 -> 716.4 | K26: =J26 -> 716.4
A28: Dividend per share | C28: 6.08 | D28: 6.68 | E28: 7.08 | F28: 7.44 | G28: =G29*G25 -> 9.1595284 | H28: =H29*H25 -> 10.27208 | I28: =I29*I25 -> 11.599458 | J28: =J29*J25 -> 13.216122 | K28: =K29*K25 -> 15.047459
A29: Dividend payout ratio | C29: =C28/C25 -> 0.6019802 | D29: =D28/D25 -> 0.55946399 | E29: =E28/E25 -> 0.60409556 | F29: =F28/F25 -> 0.60983607 | G29: =F29-($F$29-$K$29)/5 -> 0.66786885 | H29: =G29-($F$29-$K$29)/5 -> 0.72590164 | I29: =H29-($F$29-$K$29)/5 -> 0.78393443 | J29: =I29-($F$29-$K$29)/5 -> 0.84196721 | K29: 0.9
A31: Working
A32: GP margin % | C32: =C6/C4 -> 0.56968468 | D32: =D6/D4 -> 0.57123245 | E32: =E6/E4 -> 0.56755401 | F32: =F6/F4 -> 0.57410705 | G32: =AVERAGE(C32:F32) -> 0.57064455 | H32: =AVERAGE(D32:G32) -> 0.57088451 | I32: =AVERAGE(E32:H32) -> 0.57079753 | J32: =AVERAGE(F32:I32) -> 0.57160841 | K32: =AVERAGE(G32:J32) -> 0.57098375
A33: SG&A as % of sales | C33: =C8/C4 -> 0.12345253 | D33: =D8/D4 -> 0.11049659 | E33: =E8/E4 -> 0.11030093 | F33: =F8/F4 -> 0.11307551 | G33: =AVERAGE(C33:F33) -> 0.11433139 | H33: =AVERAGE(D33:G33) -> 0.1120511 | I33: =AVERAGE(E33:H33) -> 0.11243973 | J33: =AVERAGE(F33:I33) -> 0.11297443 | K33: =AVERAGE(G33:J33) -> 0.11294916
A34: EBIT margin % | C34: =C10/C4 -> 0.40421861 | D34: =D10/D4 -> 0.45685259 | E34: =E10/E4 -> 0.45187153 | F34: =F10/F4 -> 0.46095343 | G34: =AVERAGE(C34:F34) -> 0.44347404 | H34: =AVERAGE(D34:G34) -> 0.4532879 | I34: =AVERAGE(E34:H34) -> 0.45239672 | J34: =AVERAGE(F34:I34) -> 0.45252802 | K34: =AVERAGE(G34:J34) -> 0.45042167
A35: Effective tax rate % | C35: =C20/C16 -> 0.1292274 | D35: =D20/D16 -> 0.19016831 | E35: =E20/E16 -> 0.20050924 | F35: =F20/F16 -> 0.21072418 | G35: =AVERAGE(C35:F35) -> 0.18265728 | H35: =AVERAGE(D35:G35) -> 0.19601475 | I35: =AVERAGE(E35:H35) -> 0.19747636 | J35: =AVERAGE(F35:I35) -> 0.19671815 | K35: =AVERAGE(G35:J35) -> 0.19321664
A36: Net profit margin | C36: =C21/C4 -> 0.32286158 | D36: =D21/D4 -> 0.34293167 | E36: =E21/E4 -> 0.32635108 | F36: =F21/F4 -> 0.32516983 | G36: =AVERAGE(C36:F36) -> 0.32932854 | H36: =AVERAGE(D36:G36) -> 0.33094528 | I36: =AVERAGE(E36:H36) -> 0.32794868 | J36: =AVERAGE(F36:I36) -> 0.32834808 | K36: =AVERAGE(G36:J36) -> 0.32914265
A37: EBITDA | C37: =C10+C40 -> 11241.6 | D37: =D10+D40 -> 13625 | E37: =E10+E40 -> 13809.51 | F37: =F10+F40 -> 14591.59 | G37: =G10+G40 -> 13995.288 | H37: =H10+H40 -> 14730.446 | I37: =I10+I40 -> 15468.615 | J37: =J10+J40 -> 16336.748 | K37: =K10+K40 -> 17272.572
A38: EBITDA margin | C38: =C37/C4 -> 0.48490704 | D38: =D37/D4 -> 0.53443948 | E38: =E37/E4 -> 0.53277431 | F38: =F37/F4 -> 0.54274719 | G38: =G37/G4 -> 0.49427849 | H38: =H37/H4 -> 0.49796728 | I38: =I37/I4 -> 0.49723376 | J38: =J37/J4 -> 0.49818517 | K38: =K37/K4 -> 0.49720249
A39: Dividend | C39: =C28*C26 -> 4507.104 | D39: =D28*D26 -> 4891.764 | E39: =E28*E26 -> 5111.052 | F39: =F28*F26 -> 5330.016 | G39: =G28*G26 -> 6561.8862 | H39: =H28*H26 -> 7358.9183 | I39: =I28*I26 -> 8309.8515 | J39: =J28*J26 -> 9468.0301 | K39: =K28*K26 -> 10780
A40: Depreciation and amortization | C40: 1870.6 | D40: 1978 | E40: 2097 | F40: 2199 | G40: =Capex!G11 -> 1145.7673 | H40: =Capex!H11 -> 1194.0725 | I40: =Capex!I11 -> 1263.0269 | J40: =Capex!J11 -> 1342.0177 | K40: =Capex!K11 -> 1410.0018
A41: Yield on cash | D41: =-D12/AVERAGE('Balance Sheet'!C5:D5) -> 0.065893259 | E41: =-E12/AVERAGE('Balance Sheet'!D5:E5) -> 0.048902777 | F41: =-F12/AVERAGE('Balance Sheet'!E5:F5) -> 0.093060785 | G41: =AVERAGE(D41:F41) -> 0.069285607 | H41: =AVERAGE(E41:G41) -> 0.07041639 | I41: =AVERAGE(F41:H41) -> 0.077587594 | J41: =AVERAGE(G41:I41) -> 0.072429864 | K41: =AVERAGE(H41:J41) -> 0.073477949

Sheet Balance Sheet
A1: Particulars | C1: Historical | G1: Forecast
B2: Unit | C2: 2022 | D2: =C2+1 -> 2023 | E2: =D2+1 -> 2024 | F2: =E2+1 -> 2025 | G2: =F2+1 -> 2026 | H2: =G2+1 -> 2027 | I2: =H2+1 -> 2028 | J2: =I2+1 -> 2029 | K2: =J2+1 -> 2030
A3: ASSETS | B3: $
A4: Current assets:
A5: Cash and equivalents | C5: 2583.8 | D5: 4579.3 | E5: 1085 | F5: 774 | G5: =CFS!C44 -> 1516.3788 | H5: =CFS!D44 -> 3918.664 | I5: =CFS!E44 -> 4733.6335 | J5: =CFS!F44 -> 5108.8648 | K5: =CFS!G44 -> 5247.4961
A6: Accounts and notes receivable | C6: 2115 | D6: 2488 | E6: 2383 | F6: 2466 | G6: =G52 -> 2636.6823 | H6: =H52 -> 2768.6065 | I6: =I52 -> 2880.5415 | J6: =J52 -> 3041.7834 | K6: =K52 -> 3231.3577
A7: Inventories, at cost, not in excess of market | C7: 52 | D7: 52.8 | E7: 56 | F7: 61 | G7: =G56 -> 61.898394 | H7: =H56 -> 64.247324 | I7: =I56 -> 68.351331 | J7: =J56 -> 72.345775 | K7: =K56 -> 76.09108
A8: Prepaid expenses and other current assets | C8: 673.4 | D8: 866.3 | E8: 1074 | F8: 863 | G8: =G61 -> 967.40734 | H8: =H61 -> 1047.5718 | I8: =I61 -> 1112.8797 | J8: =J61 -> 1126.791 | K8: =K61 -> 1213.4317
A9: Total current assets | C9: =SUM(C5:C8) -> 5424.2 | D9: =SUM(D5:D8) -> 7986.4 | E9: =SUM(E5:E8) -> 4598 | F9: =SUM(F5:F8) -> 4164 | G9: =SUM(G5:G8) -> 5182.3668 | H9: =SUM(H5:H8) -> 7799.0897 | I9: =SUM(I5:I8) -> 8795.406 | J9: =SUM(J5:J8) -> 9349.785 | K9: =SUM(K5:K8) -> 9768.3766
A10: Other assets:
A11: Investments in and advances to affiliates | C11: 1064.5 | D11: 1080.2 | E11: 2710 | F11: 2820 | G11: =F11 -> 2820 | H11: =G11 -> 2820 | I11: =H11 -> 2820 | J11: =I11 -> 2820 | K11: =J11 -> 2820
A12: Goodwill | C12: 2900.4 | D12: 3040.4 | E12: 3145 | F12: 3354 | G12: =F12 -> 3354 | H12: =G12 -> 3354 | I12: =H12 -> 3354 | J12: =I12 -> 3354 | K12: =J12 -> 3354
A13: Miscellaneous | C13: 4707.2 | D13: 5617.8 | E13: 6095 | F13: 6331 | G13: =F13 -> 6331 | H13: =G13 -> 6331 | I13: =H13 -> 6331 | J13: =I13 -> 6331 | K13: =J13 -> 6331
A14: Lease right-of-use asset, net | C14: 12565.7 | D14: 13514.4 | E14: 13339 | F14: 14606 | G14: =G75 -> 15077.716 | H14: =H75 -> 15752.174 | I14: =I75 -> 16565.946 | J14: =J75 -> 17462.252 | K14: =K75 -> 18499.037
A15: Property and equipment, at cost | C15: 41037.6 | D15: 43570 | E15: 44177 | F15: 49290 | G15: =Capex!G6 -> 49626.426 | H15: =Capex!H6 -> 51718.657 | I15: =Capex!I6 -> 54705.268 | J15: =Capex!J6 -> 58126.585 | K15: =Capex!K6 -> 61071.166
A16: Accumulated depreciation and amortization | C16: -17264 | D16: -18662.4 | E16: -18882 | F16: -21049 | G16: =Capex!G7 -> -22194.767 | H16: =Capex!H7 -> -23388.84 | I16: =Capex!I7 -> -24651.867 | J16: =Capex!J7 -> -25993.884 | K16: =Capex!K7 -> -27403.886
A17: Total assets | C17: =C9+SUM(C11:C16) -> 50435.6 | D17: =D9+SUM(D11:D16) -> 56146.8 | E17: =E9+SUM(E11:E16) -> 55182 | F17: =F9+SUM(F11:F16) -> 59516 | G17: =G9+SUM(G11:G16) -> 60196.741 | H17: =H9+SUM(H11:H16) -> 64386.081 | I17: =I9+SUM(I11:I16) -> 67919.753 | J17: =J9+SUM(J11:J16) -> 71449.737 | K17: =K9+SUM(K11:K16) -> 74439.693
A19: LIABILITIES AND SHAREHOLDERS’ EQUITY (DEFICIT)
A20: Current liabilities:
A21: Short-term borrowings and current maturities of long-term debt | C21: 0 | D21: 2192.4 | E21: 0 | F21: 0 | G21: =F21 -> 0 | H21: =G21 -> 0 | I21: =H21 -> 0 | J21: =I21 -> 0 | K21: =J21 -> 0
A22: Accounts payable | C22: 980.2 | D22: 1102.9 | E22: 1029 | F22: 1149 | G22: =F22*(1+G66) -> 1155.6461 | H22: =G22*(1+H66) -> 1207.281 | I22: =H22*(1+I66) -> 1254.7279 | J22: =I22*(1+J66) -> 1350.3306 | K22: =J22*(1+K66) -> 1416.8399
A23: Lease liability | C23: 661.1 | D23: 688.1 | E23: 636 | F23: 694 | G23: 1321 | H23: 1289 | I23: 1239 | J23: 1201 | K23: 1156
A24: Income taxes | C24: 274.9 | D24: 705.1 | E24: 361 | F24: 250 | G24: =F24*(1+G70) -> 397.55718 | H24: =G24*(1+H70) -> 411.09215 | I24: =H24*(1+I70) -> 386.82855 | J24: =I24*(1+J70) -> 415.00866 | K24: =J24*(1+K70) -> 463.5541
A25: Other taxes | C25: 255.1 | D25: 268 | E25: 224 | F25: 247 | G25: =F25*(1+G70) -> 392.7865 | H25: =G25*(1+H70) -> 406.15905 | I25: =H25*(1+I70) -> 382.18661 | J25: =I25*(1+J70) -> 410.02855 | K25: =J25*(1+K70) -> 457.99145
A26: Accrued interest | C26: 393.4 | D26: 468.9 | E26: 482 | F26: 533 | G26: =F26*(1+G66) -> 536.08301 | H26: =G26*(1+H66) -> 560.0355 | I26: =H26*(1+I66) -> 582.04523 | J26: =I26*(1+J66) -> 626.39355 | K26: =J26*(1+K66) -> 657.24603
A27: Accrued payroll and other liabilities | C27: 1237.4 | D27: 1433.6 | E27: 1129 | F27: 1488 | G27: =F27*(1+G66) -> 1496.607 | H27: =G27*(1+H66) -> 1563.4762 | I27: =H27*(1+I66) -> 1624.9218 | J27: =I27*(1+J66) -> 1748.731 | K27: =J27*(1+K66) -> 1834.8632
A28: Total current liabilities | C28: =SUM(C21:C27) -> 3802.1 | D28: =SUM(D21:D27) -> 6859 | E28: =SUM(E21:E27) -> 3861 | F28: =SUM(F21:F27) -> 4361 | G28: =SUM(G21:G27) -> 5299.6798 | H28: =SUM(H21:H27) -> 5437.044 | I28: =SUM(I21:I27) -> 5469.71 | J28: =SUM(J21:J27) -> 5751.4923 | K28: =SUM(K21:K27) -> 5986.4947
A29: Long-term debt | C29: 35903.5 | D29: 37152.9 | E29: 38424 | F29: 39973 | G29: =Debt!C8 -> 37669.211 | H29: =Debt!D8 -> 38942.48 | I29: =Debt!E8 -> 40153.15 | J29: =Debt!F8 -> 41624.253 | K29: =Debt!G8 -> 43181.429
A30: Long-term lease liability | C30: 12134.4 | D30: 13057.7 | E30: 12887.5 | F30: 14147 | G30: =AVERAGE(C30:F30) -> 13056.65 | H30: =G30 -> 13056.65 | I30: =H30 -> 13056.65 | J30: =I30 -> 13056.65 | K30: =J30 -> 13056.65
A31: Long-term income taxes | C31: 791.9 | D31: 363.2 | E31: 343.5 | F31: 139 | G31: =F31 -> 139 | H31: =G31 -> 139 | I31: =H31 -> 139 | J31: =I31 -> 139 | K31: =J31 -> 139
A32: Deferred revenues - initial franchise fees | C32: 757.8 | D32: 790.1 | E32: 777.5 | F32: 944.5 | G32: =AVERAGE(C32:F32) -> 817.475 | H32: =G32 -> 817.475 | I32: =H32 -> 817.475 | J32: =I32 -> 817.475 | K32: =J32 -> 817.475
A33: Other long-term liabilities | C33: 1051.8 | D33: 949.7 | E33: 770.5 | F33: 703.5 | G33: =F33 -> 703.5 | H33: =G33 -> 703.5 | I33: =H33 -> 703.5 | J33: =I33 -> 703.5 | K33: =J33 -> 703.5
A34: Deferred income taxes | C34: 1997.5 | D34: 1680.9 | E34: 1914 | F34: 1038 | G34: =F34 -> 1038 | H34: =G34 -> 1038 | I34: =H34 -> 1038 | J34: =I34 -> 1038 | K34: =J34 -> 1038
A36: Preferred stock, no par value; authorized – 165.0 million shares; issued – none | C36: 0 | D36: 0 | E36: 0 | F36: 0 | G36: 0 | H36: 0 | I36: 0 | J36: 0 | K36: 0
A37: Common stock, $0.01 par value; authorized – 3.5 billion shares; issued – 1,660.6 million shares | C37: 16.6 | D37: 16.6 | E37: 17 | F37: 17 | G37: =F37 -> 17 | H37: =G37 -> 17 | I37: =H37 -> 17 | J37: =I37 -> 17 | K37: =J37 -> 17
A38: Additional paid-in capital | C38: 8547.1 | D38: 8892.9 | E38: 9281 | F38: 9641 | G38: =F38 -> 9641 | H38: =G38 -> 9641 | I38: =H38 -> 9641 | J38: =I38 -> 9641 | K38: =J38 -> 9641
A39: Retained earnings | C39: 59543.9 | D39: 63479.9 | E39: 66834 | F39: 70282 | G39: =F39+'P&L'!G21-'P&L'!G39 -> 73545.226 | H39: =G39+'P&L'!H21-'P&L'!H39 -> 76323.932 | I39: =H39+'P&L'!I21-'P&L'!I39 -> 78614.267 | J39: =I39+'P&L'!J21-'P&L'!J39 -> 80391.367 | K39: =J39+'P&L'!K21-'P&L'!K39 -> 81589.144
A40: Accumulated other comprehensive income (loss) | C40: -2486.6 | D40: -2456 | E40: -2553 | F40: -2414 | G40: =F40 -> -2414 | H40: =G40 -> -2414 | I40: =H40 -> -2414 | J40: =I40 -> -2414 | K40: =J40 -> -2414
A41: Common stock in treasury, at cost; 950.0 and 945.4 million shares | C41: -71624.4 | D41: -74640.1 | E41: -77375 | F41: -79316 | G41: =F41 -> -79316 | H41: =G41 -> -79316 | I41: =H41 -> -79316 | J41: =I41 -> -79316 | K41: =J41 -> -79316
A42: Total shareholders’ equity (deficit) | C42: =SUM(C37:C41) -> -6003.4 | D42: =SUM(D37:D41) -> -4706.7 | E42: =SUM(E37:E41) -> -3796 | F42: =SUM(F37:F41) -> -1790 | G42: =SUM(G37:G41) -> 1473.2257 | H42: =SUM(H37:H41) -> 4251.9319 | I42: =SUM(I37:I41) -> 6542.2674 | J42: =SUM(J37:J41) -> 8319.3665 | K42: =SUM(K37:K41) -> 9517.1442
...

Sheet CFS
A1: Particulars | C1: Forecast
B2: Unit | C2: 2026 | D2: =C2+1 -> 2027 | E2: =D2+1 -> 2028 | F2: =E2+1 -> 2029 | G2: =F2+1 -> 2030
B3: $
A4: Cash flow form operations
A5: Net Income | C5: ='P&L'!G21 -> 9825.1118 | D5: ='P&L'!H21 -> 10137.625 | E5: ='P&L'!I21 -> 10600.187 | F5: ='P&L'!J21 -> 11245.129 | G5: ='P&L'!K21 -> 11977.777
A6: Depreciation & Ammortization | C6: =Capex!G11 -> 1145.7673 | D6: =Capex!H11 -> 1194.0725 | E6: =Capex!I11 -> 1263.0269 | F6: =Capex!J11 -> 1342.0177 | G6: =Capex!K11 -> 1410.0018
A7: Operating assets
A8: Change in acc. & notes receivable | C8: =-('Balance Sheet'!G6-'Balance Sheet'!F6) -> -170.68228 | D8: =-('Balance Sheet'!H6-'Balance Sheet'!G6) -> -131.92423 | E8: =-('Balance Sheet'!I6-'Balance Sheet'!H6) -> -111.93497 | F8: =-('Balance Sheet'!J6-'Balance Sheet'!I6) -> -161.24188 | G8: =-('Balance Sheet'!K6-'Balance Sheet'!J6) -> -189.57439
A9: Change in Inventories | C9: =-('Balance Sheet'!G7-'Balance Sheet'!F7) -> -0.89839386 | D9: =-('Balance Sheet'!H7-'Balance Sheet'!G7) -> -2.3489304 | E9: =-('Balance Sheet'!I7-'Balance Sheet'!H7) -> -4.1040065 | F9: =-('Balance Sheet'!J7-'Balance Sheet'!I7) -> -3.9944441 | G9: =-('Balance Sheet'!K7-'Balance Sheet'!J7) -> -3.7453048
A10: Change in prepaid expenses and other CA | C10: =-('Balance Sheet'!G8-'Balance Sheet'!F8) -> -104.40734 | D10: =-('Balance Sheet'!H8-'Balance Sheet'!G8) -> -80.164474 | E10: =-('Balance Sheet'!I8-'Balance Sheet'!H8) -> -65.307865 | F10: =-('Balance Sheet'!J8-'Balance Sheet'!I8) -> -13.911343 | G10: =-('Balance Sheet'!K8-'Balance Sheet'!J8) -> -86.640687
A11: Operating liabilities (Change)
A12: Accounts payable | C12: ='Balance Sheet'!G22-'Balance Sheet'!F22 -> 6.6461163 | D12: ='Balance Sheet'!H22-'Balance Sheet'!G22 -> 51.634923 | E12: ='Balance Sheet'!I22-'Balance Sheet'!H22 -> 47.446853 | F12: ='Balance Sheet'!J22-'Balance Sheet'!I22 -> 95.602673 | G12: ='Balance Sheet'!K22-'Balance Sheet'!J22 -> 66.509369
A13: Income taxes (Current) | C13: ='Balance Sheet'!G24-'Balance Sheet'!F24 -> 147.55718 | D13: ='Balance Sheet'!H24-'Balance Sheet'!G24 -> 13.53497 | E13: ='Balance Sheet'!I24-'Balance Sheet'!H24 -> -24.263603 | F13: ='Balance Sheet'!J24-'Balance Sheet'!I24 -> 28.180106 | G13: ='Balance Sheet'!K24-'Balance Sheet'!J24 -> 48.545444
A14: Other taxes | C14: ='Balance Sheet'!G25-'Balance Sheet'!F25 -> 145.7865 | D14: ='Balance Sheet'!H25-'Balance Sheet'!G25 -> 13.372551 | E14: ='Balance Sheet'!I25-'Balance Sheet'!H25 -> -23.97244 | F14: ='Balance Sheet'!J25-'Balance Sheet'!I25 -> 27.841945 | G14: ='Balance Sheet'!K25-'Balance Sheet'!J25 -> 47.962899
A15: Accrued interest | C15: ='Balance Sheet'!G26-'Balance Sheet'!F26 -> 3.0830113 | D15: ='Balance Sheet'!H26-'Balance Sheet'!G26 -> 23.952493 | E15: ='Balance Sheet'!I26-'Balance Sheet'!H26 -> 22.009724 | F15: ='Balance Sheet'!J26-'Balance Sheet'!I26 -> 44.348324 | G15: ='Balance Sheet'!K26-'Balance Sheet'!J26 -> 30.852475
A16: Accrued payroll and other liabilities | C16: ='Balance Sheet'!G27-'Balance Sheet'!F27 -> 8.6069809 | D16: ='Balance Sheet'!H27-'Balance Sheet'!G27 -> 66.869248 | E16: ='Balance Sheet'!I27-'Balance Sheet'!H27 -> 61.445533 | F16: ='Balance Sheet'!J27-'Balance Sheet'!I27 -> 123.80921 | G16: ='Balance Sheet'!K27-'Balance Sheet'!J27 -> 86.132238
A17: Long-term income taxes | C17: ='Balance Sheet'!G31-'Balance Sheet'!F31 -> 0 | D17: ='Balance Sheet'!H31-'Balance Sheet'!G31 -> 0 | E17: ='Balance Sheet'!I31-'Balance Sheet'!H31 -> 0 | F17: ='Balance Sheet'!J31-'Balance Sheet'!I31 -> 0 | G17: ='Balance Sheet'!K31-'Balance Sheet'!J31 -> 0
A18: Deferred revenues - initial franchise fees | C18: ='Balance Sheet'!G32-'Balance Sheet'!F32 -> -127.025 | D18: ='Balance Sheet'!H32-'Balance Sheet'!G32 -> 0 | E18: ='Balance Sheet'!I32-'Balance Sheet'!H32 -> 0 | F18: ='Balance Sheet'!J32-'Balance Sheet'!I32 -> 0 | G18: ='Balance Sheet'!K32-'Balance Sheet'!J32 -> 0
A19: Other long-term liabilities | C19: ='Balance Sheet'!G33-'Balance Sheet'!F33 -> 0 | D19: ='Balance Sheet'!H33-'Balance Sheet'!G33 -> 0 | E19: ='Balance Sheet'!I33-'Balance Sheet'!H33 -> 0 | F19: ='Balance Sheet'!J33-'Balance Sheet'!I33 -> 0 | G19: ='Balance Sheet'!K33-'Balance Sheet'!J33 -> 0
A20: Deferred income taxes | C20: ='Balance Sheet'!G34-'Balance Sheet'!F34 -> 0 | D20: ='Balance Sheet'!H34-'Balance Sheet'!G34 -> 0 | E20: ='Balance Sheet'!I34-'Balance Sheet'!H34 -> 0 | F20: ='Balance Sheet'!J34-'Balance Sheet'!I34 -> 0 | G20: ='Balance Sheet'!K34-'Balance Sheet'!J34 -> 0
A21: Cash generated from operations | C21: =SUM(C5:C20) -> 10879.546 | D21: =SUM(D5:D20) -> 11286.624 | E21: =SUM(E5:E20) -> 11764.533 | F21: =SUM(F5:F20) -> 12727.781 | G21: =SUM(G5:G20) -> 13387.821
A23: Cashflow from Investing activities (Changes)
A24: Purchase of Property plant and equipment (Capex) | C24: =-Capex!G5 -> -336.42577 | D24: =-Capex!H5 -> -2092.2311 | E24: =-Capex!I5 -> -2986.6109 | F24: =-Capex!J5 -> -3421.3173 | G24: =-Capex!K5 -> -2944.5807
A25: Goodwill | C25: ='Balance Sheet'!G12-'Balance Sheet'!F12 -> 0 | D25: ='Balance Sheet'!H12-'Balance Sheet'!G12 -> 0 | E25: ='Balance Sheet'!I12-'Balance Sheet'!H12 -> 0 | F25: ='Balance Sheet'!J12-'Balance Sheet'!I12 -> 0 | G25: ='Balance Sheet'!K12-'Balance Sheet'!J12 -> 0
A26: Investments in and advances to affiliates | C26: ='Balance Sheet'!G11-'Balance Sheet'!F11 -> 0 | D26: ='Balance Sheet'!H11-'Balance Sheet'!G11 -> 0 | E26: ='Balance Sheet'!I11-'Balance Sheet'!H11 -> 0 | F26: ='Balance Sheet'!J11-'Balance Sheet'!I11 -> 0 | G26: ='Balance Sheet'!K11-'Balance Sheet'!J11 -> 0
A27: Lease Right of use assets net | C27: =-('Balance Sheet'!G14-'Balance Sheet'!F14) -> -471.71578 | D27: =-('Balance Sheet'!H14-'Balance Sheet'!G14) -> -674.45851 | E27: =-('Balance Sheet'!I14-'Balance Sheet'!H14) -> -813.77145 | F27: =-('Balance Sheet'!J14-'Balance Sheet'!I14) -> -896.30601 | G27: =-('Balance Sheet'!K14-'Balance Sheet'!J14) -> -1036.7854
A28: Cash generated from investments | C28: =SUM(C24:C27) -> -808.14155 | D28: =SUM(D24:D27) -> -2766.6896 | E28: =SUM(E24:E27) -> -3800.3823 | F28: =SUM(F24:F27) -> -4317.6233 | G28: =SUM(G24:G27) -> -3981.366
A30: Cashflow from Financing activities
A31: Net borrowings of long term debt | C31: =Debt!C6-Debt!C7 -> -2303.7895 | D31: =Debt!D6-Debt!D7 -> 1273.2695 | E31: =Debt!E6-Debt!E7 -> 1210.6702 | F31: =Debt!F6-Debt!F7 -> 1471.1031 | G31: =Debt!G6-Debt!G7 -> 1557.1758
A32: Change in Current Lease Liability | C32: ='Balance Sheet'!G23-'Balance Sheet'!F23 -> 627 | D32: ='Balance Sheet'!H23-'Balance Sheet'!G23 -> -32 | E32: ='Balance Sheet'!I23-'Balance Sheet'!H23 -> -50 | F32: ='Balance Sheet'!J23-'Balance Sheet'!I23 -> -38 | G32: ='Balance Sheet'!K23-'Balance Sheet'!J23 -> -45
A33: Change in Long-Term Lease Liability | C33: ='Balance Sheet'!G30-'Balance Sheet'!F30 -> -1090.35 | D33: ='Balance Sheet'!H30-'Balance Sheet'!G30 -> 0 | E33: ='Balance Sheet'!I30-'Balance Sheet'!H30 -> 0 | F33: ='Balance Sheet'!J30-'Balance Sheet'!I30 -> 0 | G33: ='Balance Sheet'!K30-'Balance Sheet'!J30 -> 0
A34: Change in Short-Term Borrowings and Current Long-Term Maturities | C34: ='Balance Sheet'!G21-'Balance Sheet'!F21 -> 0 | D34: ='Balance Sheet'!H21-'Balance Sheet'!G21 -> 0 | E34: ='Balance Sheet'!I21-'Balance Sheet'!H21 -> 0 | F34: ='Balance Sheet'!J21-'Balance Sheet'!I21 -> 0 | G34: ='Balance Sheet'!K21-'Balance Sheet'!J21 -> 0
A35: Preferred Stock Issuance / (Retirement) | C35: ='Balance Sheet'!G36-'Balance Sheet'!F36 -> 0 | D35: ='Balance Sheet'!H36-'Balance Sheet'!G36 -> 0 | E35: ='Balance Sheet'!I36-'Balance Sheet'!H36 -> 0 | F35: ='Balance Sheet'!J36-'Balance Sheet'!I36 -> 0 | G35: ='Balance Sheet'!K36-'Balance Sheet'!J36 -> 0
A36: Common Stock Issuance / (Retirement) | C36: ='Balance Sheet'!G38-'Balance Sheet'!F38 -> 0 | D36: ='Balance Sheet'!H38-'Balance Sheet'!G38 -> 0 | E36: ='Balance Sheet'!I38-'Balance Sheet'!H38 -> 0 | F36: ='Balance Sheet'!J38-'Balance Sheet'!I38 -> 0 | G36: ='Balance Sheet'!K38-'Balance Sheet'!J38 -> 0
A37: Change in Additional Paid-in Capital | C37: ='Balance Sheet'!G38-'Balance Sheet'!F38 -> 0 | D37: ='Balance Sheet'!H38-'Balance Sheet'!G38 -> 0 | E37: ='Balance Sheet'!I38-'Balance Sheet'!H38 -> 0 | F37: ='Balance Sheet'!J38-'Balance Sheet'!I38 -> 0 | G37: ='Balance Sheet'!K38-'Balance Sheet'!J38 -> 0
A38: Dividend | C38: =-'P&L'!G39 -> -6561.8862 | D38: =-'P&L'!H39 -> -7358.9183 | E38: =-'P&L'!I39 -> -8309.8515 | F38: =-'P&L'!J39 -> -9468.0301 | G38: =-'P&L'!K39 -> -10780
A39: Cash generated from financing activity | C39: =SUM(C31:C38) -> -9329.0256 | D39: =SUM(D31:D38) -> -6117.6487 | E39: =SUM(E31:E38) -> -7149.1813 | F39: =SUM(F31:F38) -> -8034.9269 | G39: =SUM(G31:G38) -> -9267.8238
A41: Total cash generated during year | C41: =C21+C28+C39 -> 742.37878 | D41: =D21+D28+D39 -> 2402.2852 | E41: =E21+E28+E39 -> 814.96952 | F41: =F21+F28+F39 -> 375.23125 | G41: =G21+G28+G39 -> 138.63132
A43: (+) Opening balance of cash and cash equivalents | C43: ='Balance Sheet'!F5 -> 774 | D43: =C44 -> 1516.3788 | E43: =D44 -> 3918.664 | F43: =E44 -> 4733.6335 | G43: =F44 -> 5108.8648
A44: Closing balance | C44: =C41+C43 -> 1516.3788 | D44: =D41+D43 -> 3918.664 | E44: =E41+E43 -> 4733.6335 | F44: =F41+F43 -> 5108.8648 | G44: =G41+G43 -> 5247.4961

Sheet Capex
A1: Particulars | C1: Historical | G1: Forecast
B2: Unit | C2: 2022 | D2: =C2+1 -> 2023 | E2: =D2+1 -> 2024 | F2: =E2+1 -> 2025 | G2: =F2+1 -> 2026 | H2: =G2+1 -> 2027 | I2: =H2+1 -> 2028 | J2: =I2+1 -> 2029 | K2: =J2+1 -> 2030
B3: $
A4: Opening Balance | C4: 41916.6 | D4: =C6 -> 41037.6 | E4: =D6 -> 43570 | F4: =E6 -> 44177 | G4: =F6 -> 49290 | H4: =G6 -> 49626.426 | I4: =H6 -> 51718.657 | J4: =I6 -> 54705.268 | K4: =J6 -> 58126.585
A5: (+) Net purchases | C5: =C6-C4 -> -879 | D5: =D6-D4 -> 2532.4 | E5: =E6-E4 -> 607 | F5: =F6-F4 -> 5113 | G5: =G6-G4 -> 336.42577 | H5: =H6-H4 -> 2092.2311 | I5: =I6-I4 -> 2986.6109 | J5: =J6-J4 -> 3421.3173 | K5: =K6-K4 -> 2944.5807
A6: Gross Balance | C6: 41037.6 | D6: 43570 | E6: 44177 | F6: 49290 | G6: ='P&L'!G4/Capex!G15 -> 49626.426 | H6: ='P&L'!H4/Capex!H15 -> 51718.657 | I6: ='P&L'!I4/Capex!I15 -> 54705.268 | J6: ='P&L'!J4/Capex!J15 -> 58126.585 | K6: ='P&L'!K4/Capex!K15 -> 61071.166
A7: (-) Accumulated depreciation | C7: -17264 | D7: -18662.4 | E7: -18882 | F7: -21049 | G7: =F7-G11 -> -22194.767 | H7: =G7-H11 -> -23388.84 | I7: =H7-I11 -> -24651.867 | J7: =I7-J11 -> -25993.884 | K7: =J7-K11 -> -27403.886
A8: End Balance | C8: 23773.6 | D8: 24907.6 | E8: 25295 | F8: 28241 | G8: =G6+G7 -> 27431.658 | H8: =H6+H7 -> 28329.817 | I8: =I6+I7 -> 30053.401 | J8: =J6+J7 -> 32132.701 | K8: =K6+K7 -> 33667.279
A11: depreciation | C11: =C13-C12 -> 1006.3 | D11: =D13-D12 -> 1142 | E11: =E13-E12 -> 1190 | F11: =F13-F12 -> 1138 | G11: =G6*G14 -> 1145.7673 | H11: =H6*H14 -> 1194.0725 | I11: =I6*I14 -> 1263.0269 | J11: =J6*J14 -> 1342.0177 | K11: =K6*K14 -> 1410.0018
A12: amortization | C12: 864.3 | D12: 836 | E12: 907 | F12: 1061 | G12: =0 -> 0 | H12: =0 -> 0 | I12: =0 -> 0 | J12: =0 -> 0 | K12: =0 -> 0
A13: depreciation & amotization | C13: 1870.6 | D13: 1978 | E13: 2097 | F13: 2199 | G13: =G11 -> 1145.7673 | H13: =H11 -> 1194.0725 | I13: =I11 -> 1263.0269 | J13: =J11 -> 1342.0177 | K13: =K11 -> 1410.0018
A14: Rate of depreciation | C14: =C11/C6 -> 0.024521415 | D14: =D11/D6 -> 0.026210695 | E14: =E11/E6 -> 0.026937094 | F14: =F11/F6 -> 0.023087847 | G14: =F14 -> 0.023087847 | H14: =G14 -> 0.023087847 | I14: =H14 -> 0.023087847 | J14: =I14 -> 0.023087847 | K14: =J14 -> 0.023087847
A15: Fixed Asset Turnover Rate (FATR) | C15: ='P&L'!C4/Capex!C6 -> 0.56492095 | D15: ='P&L'!D4/Capex!D6 -> 0.58512738 | E15: ='P&L'!E4/Capex!E6 -> 0.58673065 | F15: ='P&L'!F4/Capex!F6 -> 0.54543903 | G15: =AVERAGE(C15:F15) -> 0.5705545 | H15: =AVERAGE(D15:G15) -> 0.57196289 | I15: =AVERAGE(E15:H15) -> 0.56867177 | J15: =AVERAGE(F15:I15) -> 0.56415705 | K15: =AVERAGE(G15:J15) -> 0.56883655

Sheet Debt
A1: Particulars | C1: Forecast
B2: Unit | C2: 2026 | D2: =C2+1 -> 2027 | E2: =D2+1 -> 2028 | F2: =E2+1 -> 2029 | G2: =F2+1 -> 2030
B3: $
A4: Long-term debt
A5: Opening balance | C5: ='Balance Sheet'!C21+'Balance Sheet'!F29 -> 39973 | D5: =C8 -> 37669.211 | E5: =D8 -> 38942.48 | F5: =E8 -> 40153.15 | G5: =F8 -> 41624.253
A6: (+) Loan taken | C6: =C8+C7-C5 -> -2303.7895 | D6: =D8+D7-D5 -> 4474.2695 | E6: =E8+E7-E5 -> 6376.6702 | F6: =F8+F7-F5 -> 5108.1031 | G6: =G8+G7-G5 -> 4568.1758
A7: (-) Loan repaid | C7: 0 | D7: 3201 | E7: 5166 | F7: 3637 | G7: 3011
A8: Closing balance | C8: =C14*'P&L'!G37 -> 37669.211 | D8: =D14*'P&L'!H37 -> 38942.48 | E8: =E14*'P&L'!I37 -> 40153.15 | F8: =F14*'P&L'!J37 -> 41624.253 | G8: =G14*'P&L'!K37 -> 43181.429
A10: Average Interest rate | C10: 0.044 | D10: =C10 -> 0.044 | E10: =D10 -> 0.044 | F10: =E10 -> 0.044 | G10: =F10 -> 0.044
A12: Interest expenses | C12: =AVERAGE(C5:C8)*C10 -> 828.72263 | D12: =AVERAGE(D5:D8)*D10 -> 927.15656 | E12: =AVERAGE(E5:E8)*E10 -> 997.02131 | F12: =AVERAGE(F5:F8)*F10 -> 995.74758 | G12: =AVERAGE(G5:G8)*G10 -> 1016.2334
A14: Total Long term debt/EBITDA | C14: ='Balance Sheet'!G73 -> 2.6915638 | D14: ='Balance Sheet'!H73 -> 2.6436728 | E14: ='Balance Sheet'!I73 -> 2.5957819 | F14: ='Balance Sheet'!J73 -> 2.5478909 | G14: ='Balance Sheet'!K73 -> 2.5

Sheet Cost of Debt
A1: Particulars
B2: Unit
A4: Cost of debt | B4: =B17 -> 0.037416026
A5: Marginal tax rate | B5: =25% -> 0.25
A7: Market based method | F7: https://www.tradingview.com/symbols/FINRA-MCD6153327/
A8: Yield of McDonald Bond
A9: FV | B9: 100
A10: Current Market Price of Bond | B10: 100.084 | F10: We took 2036 maturity bond
A11: Valuation date | B11: 46199
A12: Redemption Date | B12: 49718
A13: Time to maturity | B13: =YEARFRAC(B12,B11,0) -> 9.6305556
A14: Coupon rate | B14: 0.05
A15: Coupon amount | B15: =B14*B9 -> 5
A16: Cost of debt. (Pre tax) | B16: =RATE(B13,B15,-B10,B9,0) -> 0.049888035
A17: Cost of debt. (Post tax) | B17: =B16*(1-B5) -> 0.037416026

Sheet Cost of Equity
A1: Details
A4: Cost of Equity | I4: mcd | J4: https://www.investing.com/equities/mcdonalds-historical-data
A5: Rist Free Rate | B5: 0.04392 | C5: https://www.investing.com/rates-bonds/u.s.-10-year-bond-yield-historical-data | I5: qsr | J5: https://www.investing.com/equities/restaurant-brands-intrnational
A6: Market Rate of Return (historic) | B6: =B16 -> 0.076796403 | I6: we | J6: https://www.investing.com/equities/the-wendys-co
A7: Re levered (Bottom up) β | B7: =B27 -> 0.57673779 | I7: yum | J7: https://www.investing.com/equities/yum!-brands-inc
A8: Cost of equity (CAPM) | B8: =B5+B7*(B6-B5) -> 0.062881064 | I8: nyse(nya) | J8: https://www.investing.com/indices/nyse-composite
A11: Date | B11: Year | C11: NYSE composit Index value
A12: 31048 | B12: 1985 | C12: 1097.02
A13: 46198 | B13: 2026 | C13: 23610.73
A15: # of Years | B15: =YEARFRAC(A12,A13,1) -> 41.479791
A16: Constant growth rate (yearly) % | B16: =(C13/C12)^(1/B15)-1 -> 0.076796403
A17: Marginal tax rate | B17: 0.25
B20: Regression β | C20: Average Market Capitalization | D20: Average Debt | E20: Total Capital | F20: Unlevered β
A21: mc | B21: =F45 -> 0.59182077 | C21: =B35 -> 213489.33 | D21: =B39 -> 36370.667 | E21: =C21+D21 -> 249860 | F21: =B21/(1+(1-$B$17)*D21/C21) -> 0.52476979
A22: we | B22: =O45 -> 0.77439387 | C22: =C35 -> 2993.3333 | D22: =C39 -> 2331.6667 | E22: =C22+D22 -> 5325 | F22: =B22/(1+(1-$B$17)*D22/C22) -> 0.4888187
A23: yum | B23: =L45 -> 0.72814674 | C23: =D35 -> 38689.333 | D23: =D39 -> 10867 | E23: =C23+D23 -> 49556.333 | F23: =B23/(1+(1-$B$17)*D23/C23) -> 0.60144668
A24: qsr | B24: =I45 -> 0.60903945 | C24: =E35 -> 22615 | D24: =E39 -> 12500.667 | E24: =C24+D24 -> 35115.667 | F24: =B24/(1+(1-$B$17)*D24/C24) -> 0.43054742
A26: Average unlevered β | B26: =AVERAGE(F21:F24) -> 0.51139565
A27: Re levered (Bottom up) β for McDonald's | B27: =B26*(1+(1-B17)*D21/C21) -> 0.57673779
B31: MacDonalds | C31: Wendys | D31: yUM | E31: qsr | I31: Note: If links don't work by clicking then you can try copying them and pasting in google which will work (We had such cases for some reason)
A32: 2023 | B32: 215071 | C32: 4028 | D32: 36625 | E32: 24379 | I32: mac | J32: https://www.marketscreener.com/quote/stock/MCDONALD-S-CORPORATION-4833/
A33: 2024 | B33: 207741 | C33: 3363 | D33: 37440 | E33: 21099 | I33: we | J33: https://www.marketscreener.com/quote/stock/THE-WENDY-S-COMPANY-9691436/
A34: 2025 | B34: 217656 | C34: 1589 | D34: 42003 | E34: 22367 | I34: yum | J34: https://www.marketscreener.com/quote/stock/YUM-BRANDS-INC-46353249/
A35: Average Market Capitalization | B35: =AVERAGE(B32:B34) -> 213489.33 | C35: =AVERAGE(C32:C34) -> 2993.3333 | D35: =AVERAGE(D32:D34) -> 38689.333 | E35: =AVERAGE(E32:E34) -> 22615 | I35: qsr | J35: https://www.marketscreener.com/quote/stock/RESTAURANT-BRANDS-INTERNA-22033517/
A36: 2023 | B36: 32574 | C36: 2246 | D36: 10683 | E36: 12250
A37: 2024 | B37: 37339 | C37: 2290 | D37: 10717 | E37: 12746
A38: 2025 | B38: 39199 | C38: 2459 | D38: 11201 | E38: 12506
A39: Average Debt | B39: =AVERAGE(B36:B38) -> 36370.667 | C39: =AVERAGE(C36:C38) -> 2331.6667 | D39: =AVERAGE(D36:D38) -> 10867 | E39: =AVERAGE(E36:E38) -> 12500.667
B44: NYSE (^NYA) | E44: mcd | H44: qsr | K44: yum | N44: wen
A45: Beta | C45: =_xlfn.COVARIANCE.S($C$50:$C$330,C50:C330)/_xlfn.VAR.S($C$50:$C$330) -> 1 | F45: =_xlfn.COVARIANCE.S($C$50:$C$330,F50:F330)/_xlfn.VAR.S($C$50:$C$330) -> 0.59182077 | I45: =_xlfn.COVARIANCE.S($C$50:$C$330,I50:I330)/_xlfn.VAR.S($C$50:$C$330) -> 0.60903945 | L45: =_xlfn.COVARIANCE.S($C$50:$C$330,L50:L330)/_xlfn.VAR.S($C$50:$C$330) -> 0.72814674 | O45: =_xlfn.COVARIANCE.S($C$50:$C$330,O50:O330)/_xlfn.VAR.S($C$50:$C$330) -> 0.77439387
A46: Regression Beta
A49: Date | B49: Price | C49: returns | E49: Price | F49: returns | H49: Price | I49: returns | K49: Price | L49: returns | N49: Price | O49: returns
A50: 46194 | B50: 23689.2 | C50: =B50/B51-1 -> 0.0080639327 | E50: 269.76 | F50: =E50/E51-1 -> -0.031764833 | H50: 74.34 | I50: =H50/H51-1 -> 0.012254902 | K50: 156.41 | L50: =K50/K51-1 -> 0.029080861 | N50: 7.8 | O50: =N50/N51-1 -> 0.14705882
A51: 46187 | B51: 23499.7 | C51: =B51/B52-1 -> -0.0040727587 | E51: 278.61 | F51: =E51/E52-1 -> -0.021768899 | H51: 73.44 | I51: =H51/H52-1 -> -0.018837675 | K51: 151.99 | L51: =K51/K52-1 -> -0.01503467 | N51: 6.8 | O51: =N51/N52-1 -> 0.0014727541
A52: 46180 | B52: 23595.8 | C52: =B52/B53-1 -> 0.01458947 | E52: 284.81 | F52: =E52/E53-1 -> 0.017760149 | H52: 74.85 | I52: =H52/H53-1 -> 0.03014038 | K52: 154.31 | L52: =K52/K53-1 -> 0.022801087 | N52: 6.79 | O52: =N52/N53-1 -> 0.011922504
A53: 46173 | B53: 23256.5 | C53: =B53/B54-1 -> -0.0015327019 | E53: 279.84 | F53: =E53/E54-1 -> 0.0022922636 | H53: 72.66 | I53: =H53/H54-1 -> -0.027309237 | K53: 150.87 | L53: =K53/K54-1 -> 0.019736397 | N53: 6.71 | O53: =N53/N54-1 -> -0.12857143
A54: 46166 | B54: 23292.2 | C54: =B54/B55-1 -> 0.0028588897 | E54: 279.2 | F54: =E54/E55-1 -> -0.010876112 | H54: 74.7 | I54: =H54/H55-1 -> -0.0090209605 | K54: 147.95 | L54: =K54/K55-1 -> -0.046406703 | N54: 7.7 | O54: =N54/N55-1 -> -0.014084507
A55: 46159 | B55: 23225.8 | C55: =B55/B56-1 -> 0.018702247 | E55: 282.27 | F55: =E55/E56-1 -> 0.021274286 | H55: 75.38 | I55: =H55/H56-1 -> -0.0060654008 | K55: 155.15 | L55: =K55/K56-1 -> 0.034540241 | N55: 7.81 | O55: =N55/N56-1 -> -0.026184539
A56: 46152 | B56: 22799.4 | C56: =B56/B57-1 -> -0.0062243377 | E56: 276.39 | F56: =E56/E57-1 -> 0.0023209429 | H56: 75.84 | I56: =H56/H57-1 -> -0.048550997 | K56: 149.97 | L56: =K56/K57-1 -> -0.013030602 | N56: 8.02 | O56: =N56/N57-1 -> 0.098630137
A57: 46145 | B57: 22942.2 | C57: =B57/B58-1 -> -0.0042966512 | E57: 275.75 | F57: =E57/E58-1 -> -0.037991906 | H57: 79.71 | I57: =H57/H58-1 -> -0.0039985006 | K57: 151.95 | L57: =K57/K58-1 -> -0.040477393 | N57: 7.3 | O57: =N57/N58-1 -> 0.089552239
...

Sheet Beta & Scatter
A1: SUMMARY OUTPUT
A3: Regression Statistics
A4: Multiple R | B4: 0.48436144
A5: R Square | B5: 0.23460601
A6: Adjusted R Square | B6: 0.23186266
A7: Standard Error | B7: 0.021194006
A8: Observations | B8: 281
A10: ANOVA
B11: df | C11: SS | D11: MS | E11: F | F11: Significance F
A12: Regression | B12: 1 | C12: 0.038413545 | D12: 0.038413545 | E12: 85.518146 | F12: 6.1750299e-18
A13: Residual | B13: 279 | C13: 0.12532287 | D13: 0.0004491859
A14: Total | B14: 280 | C14: 0.16373641
B16: Coefficients | C16: Standard Error | D16: t Stat | E16: P-value | F16: Lower 95% | G16: Upper 95% | H16: Lower 95.0% | I16: Upper 95.0%
A17: Intercept | B17: 6.9605323e-05 | C17: 0.0012696063 | D17: 0.054824336 | E17: 0.95631765 | F17: -0.0024296186 | G17: 0.0025688293 | H17: -0.0024296186 | I17: 0.0025688293
A18: X Variable 1 | B18: 0.59182077 | C18: 0.063997213 | D18: 9.2476022 | E18: 6.1750299e-18 | F18: 0.46584206 | G18: 0.71779949 | H18: 0.46584206 | I18: 0.71779949

Sheet Valuation
C1: 1 | D1: 2 | E1: 3 | F1: 4 | G1: 5
A2: Particulars | C2: Forecast
B3: Unit | C3: 2026 | D3: =C3+1 -> 2027 | E3: =D3+1 -> 2028 | F3: =E3+1 -> 2029 | G3: =F3+1 -> 2030
A4: EBIT | C4: ='P&L'!G10 -> 12849.521 | D4: ='P&L'!H10 -> 13536.374 | E4: ='P&L'!I10 -> 14205.588 | F4: ='P&L'!J10 -> 14994.731 | G4: ='P&L'!K10 -> 15862.57
A5: Tax Rate | C5: ='P&L'!G35 -> 0.18265728 | D5: =C5+($G$5-$C$5)/4 -> 0.20099296 | E5: =D5+($G$5-$C$5)/4 -> 0.21932864 | F5: =E5+($G$5-$C$5)/4 -> 0.23766432 | G5: 0.256
A6: (-) Income taxes | C6: =C5*C4 -> 2347.0586 | D6: =D5*D4 -> 2720.7158 | E6: =E5*E4 -> 3115.6923 | F6: =F5*F4 -> 3563.7125 | G6: =G5*G4 -> 4060.8179
A7: NOPAT | C7: =C4-C6 -> 10502.462 | D7: =D4-D6 -> 10815.658 | E7: =E4-E6 -> 11089.896 | F7: =F4-F6 -> 11431.018 | G7: =G4-G6 -> 11801.752
A8: (+) D&A | C8: ='P&L'!G40 -> 1145.7673 | D8: ='P&L'!H40 -> 1194.0725 | E8: ='P&L'!I40 -> 1263.0269 | F8: ='P&L'!J40 -> 1342.0177 | G8: ='P&L'!K40 -> 1410.0018
A9: (+/-) Changes in WC | C9: =SUM(CFS!C7:C10)+SUM(CFS!C12:C20) -> -91.333229 | D9: =SUM(CFS!D7:D10)+SUM(CFS!D12:D20) -> -45.07345 | E9: =SUM(CFS!E7:E10)+SUM(CFS!E12:E20) -> -98.680777 | F9: =SUM(CFS!F7:F10)+SUM(CFS!F12:F20) -> 140.63459 | G9: =SUM(CFS!G7:G10)+SUM(CFS!G12:G20) -> 0.042046112
A10: (-) Capex | C10: =-Capex!G5 -> -336.42577 | D10: =-Capex!H5 -> -2092.2311 | E10: =-Capex!I5 -> -2986.6109 | F10: =-Capex!J5 -> -3421.3173 | G10: =-Capex!K5 -> -2944.5807
A11: FCFF | C11: =SUM(C7:C10) -> 11220.471 | D11: =SUM(D7:D10) -> 9872.4258 | E11: =SUM(E7:E10) -> 9267.6309 | F11: =SUM(F7:F10) -> 9492.3533 | G11: =SUM(G7:G10) -> 10267.215
A12: FCFF growt rate | D12: =D11/C11-1 -> -0.12014156 | E12: =E11/D11-1 -> -0.061261014 | F12: =F11/E11-1 -> 0.02424809 | G12: =G11/F11-1 -> 0.081630114
A13: longrun FCFF growth rate | B13: 0.02
A15: Terminal value | G15: =G11*(1+B13)/(B17-B13) -> 267332.62
A16: Total Cash Flow | C16: =C11+C15 -> 11220.471 | D16: =D11+D15 -> 9872.4258 | E16: =E11+E15 -> 9267.6309 | F16: =F11+F15 -> 9492.3533 | G16: =G11+G15 -> 277599.84
A17: WACC | B17: ='Cost of Equity'!B8*'Cost of Equity'!C21/'Cost of Equity'!E21+'Cost of Debt'!B17*'Cost of Equity'!D21/'Cost of Equity'!E21 -> 0.059174267
A18: PV of cashflows | C18: =C16/(1+$B$17)^C1 -> 10593.602 | D18: =D16/(1+$B$17)^D1 -> 8800.1289 | E18: =E16/(1+$B$17)^E1 -> 7799.4947 | F18: =F16/(1+$B$17)^F1 -> 7542.3071 | G18: =G16/(1+$B$17)^G1 -> 208248.61
A19: Value of firm | B19: =SUM(C18:G18) -> 242984.14
A20: (-) Value of debt | B20: ='Balance Sheet'!F21+'Balance Sheet'!F23+'Balance Sheet'!F29+'Balance Sheet'!F30 -> 54814
A21: (+) Cash and cash equivalents | B21: ='Balance Sheet'!F5 -> 774
A22: (+) Investments | B22: ='Balance Sheet'!F11 -> 2820
A23: Value of equity | B23: =B19-B20+B21+B22 -> 191764.14
A24: # of shares outstanding | B24: ='P&L'!F26 -> 716.4
A25: Fair Value per share | B25: =B23/B24 -> 267.67747
A28: Sensitivity Analysis
A29: =B25 -> 267.67747 | B29: 0.044174267 | C29: 0.049174267 | D29: 0.054174267 | E29: 0.059174267 | F29: 0.064174267 | G29: 0.069174267 | H29: 0.074174267
A30: 0.014 | B30: 378.19933 | C30: 314.3524 | D30: 266.40164 | E30: 229.06864 | F30: 199.17899 | G30: 174.70901 | H30: 154.30759
A31: 0.016 | B31: 406.56191 | C31: 334.62503 | D31: 281.53582 | E31: 240.74591 | F31: 208.42555 | G31: 182.18545 | H31: 160.45775
A32: 0.018 | B32: 439.25892 | C32: 357.49887 | D32: 298.34347 | E32: 253.5576 | F32: 218.47312 | G32: 190.24628 | H32: 167.04584
A33: 0.02 | B33: 477.36614 | C33: 383.50887 | D33: 317.11841 | E33: 267.67747 | F33: 229.4305 | G33: 198.96281 | H33: 174.12038
A34: 0.022 | B34: 522.3475 | C34: 413.34749 | D34: 338.2275 | E34: 283.31665 | F34: 241.42712 | G34: 208.41843 | H34: 181.73728
A35: 0.024 | B35: 576.24742 | C35: 447.92724 | D35: 362.13488 | E35: 300.73432 | F35: 254.61821 | G35: 218.71131 | H35: 189.96143
A36: 0.026 | B36: 642.01024 | C36: 488.47564 | D36: 389.43648 | E36: 320.25213 | F36: 269.19149 | G36: 229.9578 | H36: 198.86844
